<?xml version="1.0"?>
<!-- This URDF was automatically created by SolidWorks to URDF Exporter! Originally created by Stephen Brawner (brawner@gmail.com) 
     Commit Version: 1.6.0-4-g7f85cfe  Build Version: 1.6.7995.38578
     For more information, please see http://wiki.ros.org/sw_urdf_exporter -->
<robot
  name="quadruped_model">
  <link
    name="base_link">
    <inertial>
      <origin
        xyz="-0.000327075344292646 5.887146671546E-08 0.0001873336015729"
        rpy="0 0 0" />
      <mass
        value="1.97175001857781" />
      <inertia
        ixx="0.00413387278213243"
        ixy="-1.56194941232084E-09"
        ixz="-1.96374205989058E-08"
        iyy="0.00605141396216075"
        iyz="-3.45220573999436E-07"
        izz="0.00928842475387559" />
    </inertial>
    <visual>
      <origin
        xyz="0 0 0"
        rpy="0 0 0" />
      <geometry>
        <mesh
          filename="package://quadruped_model/meshes/base_link.STL" />
      </geometry>
      <material
        name="">
        <color
          rgba="0.792156862745098 0.819607843137255 0.933333333333333 1" />
      </material>
    </visual>
    <collision>
      <origin
        xyz="0 0 0"
        rpy="0 0 0" />
      <geometry>
        <mesh
          filename="package://quadruped_model/meshes/base_link.STL" />
      </geometry>
    </collision>
  </link>
  <link
    name="leg_FR_link">
    <inertial>
      <origin
        xyz="-0.0826857446272123 -0.000241480390849952 8.61590309820734E-06"
        rpy="0 0 0" />
      <mass
        value="0.178221234723265" />
      <inertia
        ixx="8.7774873338312E-05"
        ixy="-8.34374726245329E-05"
        ixz="1.21556979202137E-07"
        iyy="0.000765734511756799"
        iyz="-3.67993252244105E-09"
        izz="0.000759166889022901" />
    </inertial>
    <visual>
      <origin
        xyz="0 0 0"
        rpy="0 0 0" />
      <geometry>
        <mesh
          filename="package://quadruped_model/meshes/leg_FR_link.STL" />
      </geometry>
      <material
        name="">
        <color
          rgba="0.792156862745098 0.819607843137255 0.933333333333333 1" />
      </material>
    </visual>
    <collision>
      <origin
        xyz="0 0 0"
        rpy="0 0 0" />
      <geometry>
        <mesh
          filename="package://quadruped_model/meshes/leg_FR_link.STL" />
      </geometry>
    </collision>
  </link>
  <joint
    name="leg_FR_joint"
    type="continuous">
    <origin
      xyz="0.23462 -0.13975 0.00072724"
      rpy="0 0 0" />
    <parent
      link="base_link" />
    <child
      link="leg_FR_link" />
    <axis
      xyz="0 1 0" />
  </joint>
  <link
    name="foot_FR_link">
    <inertial>
      <origin
        xyz="0.092342 -0.0053069 -0.0035803"
        rpy="0 0 0" />
      <mass
        value="0.083275" />
      <inertia
        ixx="1.7371E-05"
        ixy="2.5453E-05"
        ixz="1.755E-05"
        iyy="0.00046982"
        iyz="-9.8665E-07"
        izz="0.0004723" />
    </inertial>
    <visual>
      <origin
        xyz="0 0 0"
        rpy="0 0 0" />
      <geometry>
        <mesh
          filename="package://quadruped_model/meshes/foot_FR_link.STL" />
      </geometry>
      <material
        name="">
        <color
          rgba="0.66667 0.81569 1 1" />
      </material>
    </visual>
    <collision>
      <origin
        xyz="0 0 0"
        rpy="0 0 0" />
      <geometry>
        <mesh
          filename="package://quadruped_model/meshes/foot_FR_link.STL" />
      </geometry>
    </collision>
  </link>
  <joint
    name="foot_FRjoint"
    type="continuous">
    <origin
      xyz="-0.18217 -0.037449 0.00020128"
      rpy="0 0 0" />
    <parent
      link="leg_FR_link" />
    <child
      link="foot_FR_link" />
    <axis
      xyz="0 -1 0" />
  </joint>
  <link
    name="leg_FL_link">
    <inertial>
      <origin
        xyz="-0.082685744626397 0.000241480390992359 -8.61590307097999E-06"
        rpy="0 0 0" />
      <mass
        value="0.178221234721523" />
      <inertia
        ixx="8.77748733384301E-05"
        ixy="8.34374726246232E-05"
        ixz="-1.21556978984504E-07"
        iyy="0.000765734511753433"
        iyz="-3.679932508201E-09"
        izz="0.00075916688901959" />
    </inertial>
    <visual>
      <origin
        xyz="0 0 0"
        rpy="0 0 0" />
      <geometry>
        <mesh
          filename="package://quadruped_model/meshes/leg_FL_link.STL" />
      </geometry>
      <material
        name="">
        <color
          rgba="0.792156862745098 0.819607843137255 0.933333333333333 1" />
      </material>
    </visual>
    <collision>
      <origin
        xyz="0 0 0"
        rpy="0 0 0" />
      <geometry>
        <mesh
          filename="package://quadruped_model/meshes/leg_FL_link.STL" />
      </geometry>
    </collision>
  </link>
  <joint
    name="leg_FL_joint"
    type="continuous">
    <origin
      xyz="0.23462 0.13975 0.00072724"
      rpy="0 0 0" />
    <parent
      link="base_link" />
    <child
      link="leg_FL_link" />
    <axis
      xyz="0 -1 0" />
  </joint>
  <link
    name="foot_FL_link">
    <inertial>
      <origin
        xyz="0.0923409137149193 0.00530689069377432 -0.00360725485860733"
        rpy="0 0 0" />
      <mass
        value="0.0832749977968765" />
      <inertia
        ixx="1.73992269374018E-05"
        ixy="-2.54522432243975E-05"
        ixz="1.79119469155073E-05"
        iyy="0.000469818870025904"
        iyz="9.94489245925805E-07"
        izz="0.000472270332573074" />
    </inertial>
    <visual>
      <origin
        xyz="0 0 0"
        rpy="0 0 0" />
      <geometry>
        <mesh
          filename="package://quadruped_model/meshes/foot_FL_link.STL" />
      </geometry>
      <material
        name="">
        <color
          rgba="0.666666666666667 0.815686274509804 1 1" />
      </material>
    </visual>
    <collision>
      <origin
        xyz="0 0 0"
        rpy="0 0 0" />
      <geometry>
        <mesh
          filename="package://quadruped_model/meshes/foot_FL_link.STL" />
      </geometry>
    </collision>
  </link>
  <joint
    name="foot_FL_joint"
    type="continuous">
    <origin
      xyz="-0.18217 0.037449 0.00020125"
      rpy="0 0 0" />
    <parent
      link="leg_FL_link" />
    <child
      link="foot_FL_link" />
    <axis
      xyz="0 1 0" />
  </joint>
  <link
    name="leg_BR_link">
    <inertial>
      <origin
        xyz="0.0826857447177423 -0.000241480460783455 -8.61590779272468E-06"
        rpy="0 0 0" />
      <mass
        value="0.178221234390122" />
      <inertia
        ixx="8.77748726433444E-05"
        ixy="8.34374721917653E-05"
        ixz="1.2155695333197E-07"
        iyy="0.000765734511459626"
        iyz="3.67997204974431E-09"
        izz="0.000759166888033231" />
    </inertial>
    <visual>
      <origin
        xyz="0 0 0"
        rpy="0 0 0" />
      <geometry>
        <mesh
          filename="package://quadruped_model/meshes/leg_BR_link.STL" />
      </geometry>
      <material
        name="">
        <color
          rgba="0.792156862745098 0.819607843137255 0.933333333333333 1" />
      </material>
    </visual>
    <collision>
      <origin
        xyz="0 0 0"
        rpy="0 0 0" />
      <geometry>
        <mesh
          filename="package://quadruped_model/meshes/leg_BR_link.STL" />
      </geometry>
    </collision>
  </link>
  <joint
    name="leg_BR_joint"
    type="continuous">
    <origin
      xyz="-0.23338 -0.13975 0.00072724"
      rpy="0 0 0" />
    <parent
      link="base_link" />
    <child
      link="leg_BR_link" />
    <axis
      xyz="0 1 0" />
  </joint>
  <link
    name="foot_BR_link">
    <inertial>
      <origin
        xyz="-0.0923409140339695 -0.00530689070203466 -0.00360725491622341"
        rpy="0 0 0" />
      <mass
        value="0.083274998233357" />
      <inertia
        ixx="1.73992270015404E-05"
        ixy="-2.54522432933655E-05"
        ixz="-1.79119472244808E-05"
        iyy="0.000469818871794177"
        iyz="-9.94489258429288E-07"
        izz="0.000472270334294119" />
    </inertial>
    <visual>
      <origin
        xyz="0 0 0"
        rpy="0 0 0" />
      <geometry>
        <mesh
          filename="package://quadruped_model/meshes/foot_BR_link.STL" />
      </geometry>
      <material
        name="">
        <color
          rgba="0.666666666666667 0.815686274509804 1 1" />
      </material>
    </visual>
    <collision>
      <origin
        xyz="0 0 0"
        rpy="0 0 0" />
      <geometry>
        <mesh
          filename="package://quadruped_model/meshes/foot_BR_link.STL" />
      </geometry>
    </collision>
  </link>
  <joint
    name="foot_BR_joint"
    type="continuous">
    <origin
      xyz="0.18217 -0.037449 0.00020125"
      rpy="0 0 0" />
    <parent
      link="leg_BR_link" />
    <child
      link="foot_BR_link" />
    <axis
      xyz="0 -1 0" />
  </joint>
  <link
    name="leg_BL_link">
    <inertial>
      <origin
        xyz="0.0826857447177424 0.000241480460783372 8.61590779267177E-06"
        rpy="0 0 0" />
      <mass
        value="0.178221234390122" />
      <inertia
        ixx="8.77748726430811E-05"
        ixy="-8.34374721917668E-05"
        ixz="-1.21556953330775E-07"
        iyy="0.000765734511459625"
        iyz="3.6799720498976E-09"
        izz="0.000759166888032966" />
    </inertial>
    <visual>
      <origin
        xyz="0 0 0"
        rpy="0 0 0" />
      <geometry>
        <mesh
          filename="package://quadruped_model/meshes/leg_BL_link.STL" />
      </geometry>
      <material
        name="">
        <color
          rgba="0.792156862745098 0.819607843137255 0.933333333333333 1" />
      </material>
    </visual>
    <collision>
      <origin
        xyz="0 0 0"
        rpy="0 0 0" />
      <geometry>
        <mesh
          filename="package://quadruped_model/meshes/leg_BL_link.STL" />
      </geometry>
    </collision>
  </link>
  <joint
    name="leg_BL_joint"
    type="continuous">
    <origin
      xyz="-0.23338 0.13975 0.00072724"
      rpy="0 0 0" />
    <parent
      link="base_link" />
    <child
      link="leg_BL_link" />
    <axis
      xyz="0 -1 0" />
  </joint>
  <link
    name="foot_BL_link">
    <inertial>
      <origin
        xyz="-0.0923419406342053 0.00530688967822675 -0.00358028192965327"
        rpy="0 0 0" />
      <mass
        value="0.0832749890421821" />
      <inertia
        ixx="1.73709950239305E-05"
        ixy="2.54525599387942E-05"
        ixz="-1.75497249118956E-05"
        iyy="0.000469818716337466"
        iyz="9.86649841263403E-07"
        izz="0.000472298412305655" />
    </inertial>
    <visual>
      <origin
        xyz="0 0 0"
        rpy="0 0 0" />
      <geometry>
        <mesh
          filename="package://quadruped_model/meshes/foot_BL_link.STL" />
      </geometry>
      <material
        name="">
        <color
          rgba="0.666666666666667 0.815686274509804 1 1" />
      </material>
    </visual>
    <collision>
      <origin
        xyz="0 0 0"
        rpy="0 0 0" />
      <geometry>
        <mesh
          filename="package://quadruped_model/meshes/foot_BL_link.STL" />
      </geometry>
    </collision>
  </link>
  <joint
    name="foot_BL_joint"
    type="continuous">
    <origin
      xyz="0.18217 0.037449 0.00020128"
      rpy="0 0 0" />
    <parent
      link="leg_BL_link" />
    <child
      link="foot_BL_link" />
    <axis
      xyz="0 1 0" />
  </joint>
</robot>
